<?xml version="1.0" ?><!-- =================================================================================== --><!-- |    This document was autogenerated by xacro from /app/install/kapibara/share/kapibara/description/kapibara.urdf.xacro | --><!-- |    EDITING THIS FILE BY HAND IS NOT RECOMMENDED                                 | --><!-- =================================================================================== --><robot name="robot"><!-- Specify some standard inertial calculations https://en.wikipedia.org/wiki/List_of_moments_of_inertia --><!-- These make use of xacro's mathematical functionality --><material name="white"><color rgba="1 1 1 1"/></material><material name="orange"><color rgba="1 0.3 0.1 1"/></material><material name="black"><color rgba="0 0 0 1"/></material><material name="red"><color rgba="1 0 0 1"/></material><!-- BASE LINK --><link name="KapiBara_base_link">
    
    </link><!-- CHASSIS LINK --><joint name="KapiBara_chassis_joint" type="fixed"><parent link="KapiBara_base_link"/><child link="KapiBara_chassis"/><origin xyz="0 0 0"/></joint><link name="KapiBara_chassis"><visual><origin xyz="0 0 0"/><geometry><mesh filename="file:///app/install/kapibara/share/kapibara/meshes/Bottom.stl" scale="0.001 0.001 0.001"/></geometry><material name="black"/></visual></link><!-- Base --><joint name="KapiBara_base_joint" type="fixed"><parent link="KapiBara_chassis"/><child link="KapiBara_base"/><origin rpy="0 0 3.141592653589793" xyz="-0.027 0 0.05"/></joint><link name="KapiBara_base"><visual><origin xyz="0 0 0.05"/><geometry><mesh filename="file:///app/install/kapibara/share/kapibara/meshes/Top.stl" scale="0.001 0.001 0.001"/></geometry><material name="orange"/></visual><collision name="base_collision"><origin xyz="-0.02 0 0.07"/><geometry><box size="0.279 0.134 0.15"/></geometry></collision><inertial><origin rpy="0 0 0" xyz="-0.02 0 0.07"/><mass value="1.15"/><inertia ixx="0.003877033333333334" ixy="0.0" ixz="0.0" iyy="0.0096160125" iyz="0.0" izz="0.009180545833333335"/></inertial></link><!-- LEFT WHEEL LINK --><joint name="KapiBara_wheel_left1_joint" type="continuous"><parent link="KapiBara_chassis"/><child link="KapiBara_left_wheel1"/><axis xyz="0 0 1"/><origin rpy="-1.5707963267948966 0 0" xyz="0.065 0.066 0.0135"/><!-- <joint_properties damping="1.0" friction="1.0" />  --><limit effort="10000" velocity="1000"/></joint><link name="KapiBara_left_wheel1"><visual><origin xyz="0 0 0"/><geometry><cylinder length="0.044" radius="0.024"/></geometry><material name="white"/></visual><collision><origin xyz="0 0 0"/><geometry><cylinder length="0.044" radius="0.024"/></geometry></collision><inertial><origin rpy="0 0 0" xyz="0 0 0"/><mass value="0.1"/><inertia ixx="3.053333333333333e-05" ixy="0.0" ixz="0.0" iyy="3.053333333333333e-05" iyz="0.0" izz="2.8800000000000002e-05"/></inertial></link><joint name="KapiBara_wheel_left2_joint" type="continuous"><mimic joint="KapiBara_wheel_left1_joint" multiplier="1" offset="0"/><parent link="KapiBara_chassis"/><child link="KapiBara_left_wheel2"/><axis xyz="0 0 1"/><origin rpy="-1.5707963267948966 0 0" xyz="0.005 0.066 0.0135"/><limit effort="10000" velocity="1000"/></joint><link name="KapiBara_left_wheel2"><visual><origin xyz="0 0 0"/><geometry><cylinder length="0.044" radius="0.024"/></geometry><material name="white"/></visual><collision><origin xyz="0 0 0"/><geometry><cylinder length="0.044" radius="0.024"/></geometry></collision><inertial><origin rpy="0 0 0" xyz="0 0 0"/><mass value="0.1"/><inertia ixx="3.053333333333333e-05" ixy="0.0" ixz="0.0" iyy="3.053333333333333e-05" iyz="0.0" izz="2.8800000000000002e-05"/></inertial></link><joint name="KapiBara_wheel_left3_joint" type="continuous"><mimic joint="KapiBara_wheel_left1_joint" multiplier="1" offset="0"/><parent link="KapiBara_chassis"/><child link="KapiBara_left_wheel3"/><axis xyz="0 0 1"/><origin rpy="-1.5707963267948966 0 0" xyz="-0.055 0.066 0.0135"/><limit effort="10000" velocity="1000"/></joint><link name="KapiBara_left_wheel3"><visual><origin xyz="0 0 0"/><geometry><cylinder length="0.044" radius="0.024"/></geometry><material name="white"/></visual><collision><origin xyz="0 0 0"/><geometry><cylinder length="0.044" radius="0.024"/></geometry></collision><inertial><origin rpy="0 0 0" xyz="0 0 0"/><mass value="0.1"/><inertia ixx="3.053333333333333e-05" ixy="0.0" ixz="0.0" iyy="3.053333333333333e-05" iyz="0.0" izz="2.8800000000000002e-05"/></inertial></link><!-- RIGHT WHEEL LINK --><joint name="KapiBara_wheel_right2_joint" type="continuous"><mimic joint="KapiBara_wheel_right3_joint" multiplier="1" offset="0"/><parent link="KapiBara_chassis"/><child link="KapiBara_right_wheel1"/><axis xyz="0 0 1"/><origin rpy="-1.5707963267948966 0 0" xyz="0.005 -0.066 0.0135"/><!-- <joint_properties damping="1.0" friction="1.0" />  --><!-- <limit effort="10000" velocity="1000"/>  --></joint><link name="KapiBara_right_wheel1"><visual><origin xyz="0 0 0"/><geometry><cylinder length="0.044" radius="0.024"/></geometry><material name="white"/></visual><collision><origin xyz="0 0 0"/><geometry><cylinder length="0.044" radius="0.024"/></geometry></collision><inertial><origin rpy="0 0 0" xyz="0 0 0"/><mass value="0.1"/><inertia ixx="3.053333333333333e-05" ixy="0.0" ixz="0.0" iyy="3.053333333333333e-05" iyz="0.0" izz="2.8800000000000002e-05"/></inertial></link><joint name="KapiBara_wheel_right1_joint" type="continuous"><mimic joint="KapiBara_wheel_right3_joint" multiplier="1" offset="0"/><parent link="KapiBara_chassis"/><child link="KapiBara_right_wheel2"/><axis xyz="0 0 1"/><origin rpy="-1.5707963267948966 0 0" xyz="0.065 -0.066 0.0135"/></joint><link name="KapiBara_right_wheel2"><visual><origin xyz="0 0 0"/><geometry><cylinder length="0.044" radius="0.024"/></geometry><material name="white"/></visual><collision><origin xyz="0 0 0"/><geometry><cylinder length="0.044" radius="0.024"/></geometry></collision><inertial><origin rpy="0 0 0" xyz="0 0 0"/><mass value="0.1"/><inertia ixx="3.053333333333333e-05" ixy="0.0" ixz="0.0" iyy="3.053333333333333e-05" iyz="0.0" izz="2.8800000000000002e-05"/></inertial></link><joint name="KapiBara_wheel_right3_joint" type="continuous"><parent link="KapiBara_chassis"/><child link="KapiBara_right_wheel3"/><axis xyz="0 0 1"/><origin rpy="-1.5707963267948966 0 0" xyz="-0.055 -0.066 0.0135"/></joint><link name="KapiBara_right_wheel3"><visual><origin xyz="0 0 0"/><geometry><cylinder length="0.044" radius="0.024"/></geometry><material name="white"/></visual><collision><origin xyz="0 0 0"/><geometry><cylinder length="0.044" radius="0.024"/></geometry></collision><inertial><origin rpy="0 0 0" xyz="0 0 0"/><mass value="0.1"/><inertia ixx="3.053333333333333e-05" ixy="0.0" ixz="0.0" iyy="3.053333333333333e-05" iyz="0.0" izz="2.8800000000000002e-05"/></inertial></link><!-- EARS --><joint name="KapiBara_left_ear_joint" type="revolute"><parent link="KapiBara_base"/><child link="KapiBara_left_ear"/><axis xyz="0 -1 0"/><origin rpy="0 1.5707963267948966 0" xyz="-0.09 0.075 0.09"/><limit effort="1" lower="0" upper="3.141592653589793" velocity="1"/></joint><link name="KapiBara_left_ear"><visual><origin xyz="0 0 0"/><geometry><mesh filename="package://kapibara/meshes/Wing1.stl" scale="0.001 0.001 0.001"/></geometry><material name="white"/></visual><collision><origin rpy="1.5707963267948966 0 0" xyz="0 0 0"/><geometry><cylinder length="0.01" radius="0.024"/></geometry></collision><inertial><origin rpy="1.5707963267948966 0 0" xyz="0 0 0"/><mass value="0.1"/><inertia ixx="1.5233333333333335e-05" ixy="0.0" ixz="0.0" iyy="1.5233333333333335e-05" iyz="0.0" izz="2.8800000000000002e-05"/></inertial></link><joint name="KapiBara_right_ear_joint" type="revolute"><parent link="KapiBara_base"/><child link="KapiBara_righ_ear"/><axis xyz="0 -1 0"/><origin rpy="0 1.5707963267948966 0" xyz="-0.09 -0.070 0.09"/><limit effort="1" lower="0" upper="3.141592653589793" velocity="1"/></joint><link name="KapiBara_righ_ear"><visual><origin xyz="0 0 0"/><geometry><mesh filename="package://kapibara/meshes/Wing2.stl" scale="0.001 0.001 0.001"/></geometry><material name="white"/></visual><collision><origin rpy="1.5707963267948966 0 0" xyz="0 0 0"/><geometry><cylinder length="0.01" radius="0.024"/></geometry></collision><inertial><origin rpy="1.5707963267948966 0 0" xyz="0 0 0"/><mass value="0.1"/><inertia ixx="1.5233333333333335e-05" ixy="0.0" ixz="0.0" iyy="1.5233333333333335e-05" iyz="0.0" izz="2.8800000000000002e-05"/></inertial></link><joint name="KapiBara_camera_joint" type="fixed"><parent link="KapiBara_base"/><child link="KapiBara_camera"/><origin rpy="0 0 3.141592653589793" xyz="-0.10 0.0 0.15"/></joint><link name="KapiBara_camera"><visual><geometry><box size="0.01 0.03 0.03"/></geometry><material name="black"/></visual></link><joint name="KapiBara_camera_optical_joint" type="fixed"><parent link="KapiBara_camera"/><child link="KapiBara_camera_optical"/><origin rpy="-1.5707963267948966 0 -1.5707963267948966" xyz="0 0 0"/></joint><link name="KapiBara_camera_optical">
    </link><gazebo reference="KapiBara_camera"><material>Gazebo/Black</material><sensor name="camera" type="depth"><pose> 0 0 0 0 0 0 </pose><visualize>true</visualize><update_rate>30</update_rate><camera><horizontal_fov>0.99</horizontal_fov><vertical_fov>0.75</vertical_fov><image><format>R8G8B8</format><width>320</width><height>240</height></image><clip><near>0.012</near><far>8.0</far></clip><depth_camera><clip><near>0.4</near><far>3.5</far></clip></depth_camera></camera></sensor></gazebo><joint name="KapiBara_imu_joint" type="fixed"><parent link="KapiBara_chassis"/><child link="KapiBara_imu_link"/><origin rpy="0 0 0" xyz="0 0 0"/></joint><link name="KapiBara_imu_link">
    </link><ros2_control name="MujocoSystem" type="system"><hardware><plugin>mujoco_ros2_control/MujocoSystemInterface</plugin><param name="mujoco_model">/app/install/kapibara/share/kapibara/scenes/scene.xml</param></hardware><sensor name="kapibara_imu"><!-- <param name="mujoco_orientation_sensor_name">kapibara_imu_orientation</param>
                <param name="mujoco_angular_velocity_sensor_name">kapibara_imu_angular_velocity</param>
                <param name="mujoco_linear_acceleration_sensor_name">kapibara_imu_linear_acceleration</param> --><param name="mujoco_type">imu</param><param name="mujoco_sensor_name">kapibara_imu</param><state_interface name="orientation.x"/><state_interface name="orientation.y"/><state_interface name="orientation.z"/><state_interface name="orientation.w"/><state_interface name="angular_velocity.x"/><state_interface name="angular_velocity.y"/><state_interface name="angular_velocity.z"/><state_interface name="linear_acceleration.x"/><state_interface name="linear_acceleration.y"/><state_interface name="linear_acceleration.z"/></sensor><joint name="KapiBara_wheel_left1_joint"><command_interface name="velocity"><param name="min">-10</param><param name="max">10</param></command_interface><state_interface name="velocity"/><state_interface name="position"/></joint><joint name="KapiBara_wheel_left2_joint"><!-- <command_interface name="velocity">
                    <param name="min">-10</param>
                    <param name="max">10</param>
                </command_interface> --><state_interface name="velocity"/><state_interface name="position"/><param name="mimic">KapiBara_wheel_left1_joint</param><param name="multiplier">1</param></joint><joint name="KapiBara_wheel_left3_joint"><!-- <command_interface name="velocity">
                    <param name="min">-10</param>
                    <param name="max">10</param>
                </command_interface> --><state_interface name="velocity"/><state_interface name="position"/><param name="mimic">KapiBara_wheel_left1_joint</param><param name="multiplier">1</param></joint><joint name="KapiBara_wheel_right3_joint"><command_interface name="velocity"><param name="min">-10</param><param name="max">10</param></command_interface><state_interface name="velocity"/><state_interface name="position"/></joint><joint name="KapiBara_wheel_right2_joint"><!-- <command_interface name="velocity">
                    <param name="min">-10</param>
                    <param name="max">10</param>
                </command_interface> --><state_interface name="velocity"/><state_interface name="position"/><param name="mimic">KapiBara_wheel_right3_joint</param><param name="multiplier">1</param></joint><joint name="KapiBara_wheel_right1_joint"><!-- <command_interface name="velocity">
                    <param name="min">-10</param>
                    <param name="max">10</param>
                </command_interface> --><state_interface name="velocity"/><state_interface name="position"/><param name="mimic">KapiBara_wheel_right3_joint</param><param name="multiplier">1</param></joint><joint name="KapiBara_right_ear_joint"><command_interface name="position"><param name="min">-10</param><param name="max">10</param></command_interface><state_interface name="position"/></joint><joint name="KapiBara_left_ear_joint"><command_interface name="position"><param name="min">-10</param><param name="max">10</param></command_interface><state_interface name="position"/></joint></ros2_control></robot>